Workbook

Sheet Assumptions
A1: FitCircle Pro — subscription model assumptions (Base scenario)
A2: Edit column B. The Model and Unit Economics sheets recompute. Alternate scenarios on the Scenarios sheet.
A4: Growth
A5: installs0 | B5: 12000 | C5: Installs in month 1 (organic + paid, before viral amplification)
A6: growth | B6: 0.1 | C6: Install growth per month
A7: kfactor | B7: 0.4 | C7: Viral K-factor; amplification = 1/(1-K). GTM target 0.4 → 0.7
A8: d30 | B8: 0.1 | C8: D30 retention (GTM gate ≥10%)
A9: decay | B9: 0.85 | C9: Monthly retention decay after month 1
A10: dauMau | B10: 0.25 | C10: DAU / MAU
A11: Funnel
A12: installTrial | B12: 0.04 | C12: Install → trial. Health&Fitness median 6.9% (RevenueCat SOSA 2026)
A13: trialPaid | B13: 0.38 | C13: Trial → paid. Category median 37.7%
A14: drip | B14: 0.002 | C14: Free → paid drip per month
A15: annualShare | B15: 0.65 | C15: Annual share of new subs (category: 67-68%)
A16: mixIos | B16: 0.6 | C16: Platform mix — iOS
A17: mixAndroid | B17: 0.25 | C17: Platform mix — Android (web = remainder)
A18: Pricing & promo
A19: priceM | B19: 9.99 | C19: Pro monthly
A20: priceA | B20: 59.99 | C20: Pro annual (hero plan)
A21: priceL | B21: 149.99 | C21: Pro lifetime (launch window one-time)
A22: lifeTake | B22: 0.03 | C22: Share of new paid choosing lifetime during window
A23: lifeWindow | B23: 3 | C23: Lifetime window (months)
A24: promoPrice | B24: 39.99 | C24: Promo: annual first-year price (renews at list)
A25: promoWindow | B25: 3 | C25: Promo window in months (0 = off)
A26: promoUptake | B26: 0.7 | C26: Share of annual buyers taking the promo during window
A27: Churn
A28: churnM | B28: 0.06 | C28: Monthly-plan churn per month
A29: renewA | B29: 0.45 | C29: Annual renewal rate at each anniversary
A30: Fees & costs
A31: feeApple | B31: 0.15 | C31: Apple Small Business Program
A32: feeGoogle | B32: 0.15 | C32: Google Play effective (10% service + 5% billing, post-June-2026 US)
A33: feeWebPct | B33: 0.034 | C33: Stripe 2.9% + 0.5% Billing (30¢/txn applied separately)
A34: rcOn | B34: 1 | C34: RevenueCat 1% past $2.5K MTR (1 = on)
A35: aiFree | B35: 0.4 | C35: AI cost per free MAU per month (5 parses + 5 Fitzy msgs/day cap)
A36: aiPro | B36: 2 | C36: AI cost per Pro subscriber per month
A37: ecpm | B37: 8 | C37: Ads eCPM (free tier only; Pro is ad-free)
A38: impsDau | B38: 3 | C38: Ad impressions per DAU per day
A39: cpi | B39: 3 | C39: Blended CPI for paid UA (GTM guardrail ≤$3.50 iOS / ≤$2 Android)
A41: Derived
A42: Viral amplification 1/(1-K) | B42: =1/(1-Assumptions!$B$7)
...

Sheet Model
A1: Month | B1: Installs | C1: RetainedTail | D1: MAU | E1: Trials | F1: NewPaid | G1: NewLifetime | H1: NewMonthly | I1: NewAnnual | J1: EffAnnualPrice | K1: MonthlySubs | L1: AnnualYoung | M1: AnnualRenewed | N1: AnnualSubs | O1: LifetimeOwners | P1: Paying | Q1: RevMonthly | R1: RevAnnual | S1: RevLifetime | T1: FreeMAU | U1: FreeDAU | V1: RevAds | W1: GrossSubRev | X1: TxnFees | Y1: RCFee | Z1: NetSubRev | AA1: GrossMRR | AB1: NetMRR | AC1: AICost | AD1: CumInstalls | AE1: NetRevenueTotal
A2: 1 | B2: =Assumptions!$B$5*(1+Assumptions!$B$6)^(A2-1)*Assumptions!$B$42 | C2: 0 | D2: =B2+C2 | E2: =B2*Assumptions!$B$12 | F2: =E2*Assumptions!$B$13+D2*Assumptions!$B$14 | G2: =IF(A2<=Assumptions!$B$23,F2*Assumptions!$B$22,0) | H2: =(F2-G2)*(1-Assumptions!$B$15) | I2: =(F2-G2)*Assumptions!$B$15 | J2: =IF(A2<=Assumptions!$B$25,Assumptions!$B$46,Assumptions!$B$20) | K2: =H2 | L2: =SUM(I2:I2) | M2: 0 | N2: =L2+M2 | O2: =G2 | P2: =K2+N2+O2 | Q2: =K2*Assumptions!$B$19 | R2: =SUMPRODUCT(I2:I2,J2:J2)/12+M2*Assumptions!$B$20/12 | S2: =G2*Assumptions!$B$21 | T2: =MAX(D2-P2,0) | U2: =T2*Assumptions!$B$10 | V2: =U2*Assumptions!$B$38*Assumptions!$B$37/1000*30.4 | W2: =Q2+R2+S2 | X2: =Assumptions!$B$43*(F2+K2)*0.3 | Y2: =IF(AND(Assumptions!$B$34=1,W2>2500),W2*0.01,0) | Z2: =W2*(1-Assumptions!$B$44)-X2-Y2 | AA2: =Q2+R2 | AB2: =AA2*(1-Assumptions!$B$44)-IF(AND(Assumptions!$B$34=1,W2>2500),AA2*0.01,0) | AC2: =T2*Assumptions!$B$35+P2*Assumptions!$B$36 | AD2: =B2 | AE2: =Z2+V2
A3: 2 | B3: =Assumptions!$B$5*(1+Assumptions!$B$6)^(A3-1)*Assumptions!$B$42 | C3: =Assumptions!$B$9*C2+B2*Assumptions!$B$8 | D3: =B3+C3 | E3: =B3*Assumptions!$B$12 | F3: =E3*Assumptions!$B$13+D3*Assumptions!$B$14 | G3: =IF(A3<=Assumptions!$B$23,F3*Assumptions!$B$22,0) | H3: =(F3-G3)*(1-Assumptions!$B$15) | I3: =(F3-G3)*Assumptions!$B$15 | J3: =IF(A3<=Assumptions!$B$25,Assumptions!$B$46,Assumptions!$B$20) | K3: =K2*(1-Assumptions!$B$28)+H3 | L3: =SUM(I2:I3) | M3: 0 | N3: =L3+M3 | O3: =O2+G3 | P3: =K3+N3+O3 | Q3: =K3*Assumptions!$B$19 | R3: =SUMPRODUCT(I2:I3,J2:J3)/12+M3*Assumptions!$B$20/12 | S3: =G3*Assumptions!$B$21 | T3: =MAX(D3-P3,0) | U3: =T3*Assumptions!$B$10 | V3: =U3*Assumptions!$B$38*Assumptions!$B$37/1000*30.4 | W3: =Q3+R3+S3 | X3: =Assumptions!$B$43*(F3+K3)*0.3 | Y3: =IF(AND(Assumptions!$B$34=1,W3>2500),W3*0.01,0) | Z3: =W3*(1-Assumptions!$B$44)-X3-Y3 | AA3: =Q3+R3 | AB3: =AA3*(1-Assumptions!$B$44)-IF(AND(Assumptions!$B$34=1,W3>2500),AA3*0.01,0) | AC3: =T3*Assumptions!$B$35+P3*Assumptions!$B$36 | AD3: =AD2+B3 | AE3: =Z3+V3
A4: 3 | B4: =Assumptions!$B$5*(1+Assumptions!$B$6)^(A4-1)*Assumptions!$B$42 | C4: =Assumptions!$B$9*C3+B3*Assumptions!$B$8 | D4: =B4+C4 | E4: =B4*Assumptions!$B$12 | F4: =E4*Assumptions!$B$13+D4*Assumptions!$B$14 | G4: =IF(A4<=Assumptions!$B$23,F4*Assumptions!$B$22,0) | H4: =(F4-G4)*(1-Assumptions!$B$15) | I4: =(F4-G4)*Assumptions!$B$15 | J4: =IF(A4<=Assumptions!$B$25,Assumptions!$B$46,Assumptions!$B$20) | K4: =K3*(1-Assumptions!$B$28)+H4 | L4: =SUM(I2:I4) | M4: 0 | N4: =L4+M4 | O4: =O3+G4 | P4: =K4+N4+O4 | Q4: =K4*Assumptions!$B$19 | R4: =SUMPRODUCT(I2:I4,J2:J4)/12+M4*Assumptions!$B$20/12 | S4: =G4*Assumptions!$B$21 | T4: =MAX(D4-P4,0) | U4: =T4*Assumptions!$B$10 | V4: =U4*Assumptions!$B$38*Assumptions!$B$37/1000*30.4 | W4: =Q4+R4+S4 | X4: =Assumptions!$B$43*(F4+K4)*0.3 | Y4: =IF(AND(Assumptions!$B$34=1,W4>2500),W4*0.01,0) | Z4: =W4*(1-Assumptions!$B$44)-X4-Y4 | AA4: =Q4+R4 | AB4: =AA4*(1-Assumptions!$B$44)-IF(AND(Assumptions!$B$34=1,W4>2500),AA4*0.01,0) | AC4: =T4*Assumptions!$B$35+P4*Assumptions!$B$36 | AD4: =AD3+B4 | AE4: =Z4+V4
A5: 4 | B5: =Assumptions!$B$5*(1+Assumptions!$B$6)^(A5-1)*Assumptions!$B$42 | C5: =Assumptions!$B$9*C4+B4*Assumptions!$B$8 | D5: =B5+C5 | E5: =B5*Assumptions!$B$12 | F5: =E5*Assumptions!$B$13+D5*Assumptions!$B$14 | G5: =IF(A5<=Assumptions!$B$23,F5*Assumptions!$B$22,0) | H5: =(F5-G5)*(1-Assumptions!$B$15) | I5: =(F5-G5)*Assumptions!$B$15 | J5: =IF(A5<=Assumptions!$B$25,Assumptions!$B$46,Assumptions!$B$20) | K5: =K4*(1-Assumptions!$B$28)+H5 | L5: =SUM(I2:I5) | M5: 0 | N5: =L5+M5 | O5: =O4+G5 | P5: =K5+N5+O5 | Q5: =K5*Assumptions!$B$19 | R5: =SUMPRODUCT(I2:I5,J2:J5)/12+M5*Assumptions!$B$20/12 | S5: =G5*Assumptions!$B$21 | T5: =MAX(D5-P5,0) | U5: =T5*Assumptions!$B$10 | V5: =U5*Assumptions!$B$38*Assumptions!$B$37/1000*30.4 | W5: =Q5+R5+S5 | X5: =Assumptions!$B$43*(F5+K5)*0.3 | Y5: =IF(AND(Assumptions!$B$34=1,W5>2500),W5*0.01,0) | Z5: =W5*(1-Assumptions!$B$44)-X5-Y5 | AA5: =Q5+R5 | AB5: =AA5*(1-Assumptions!$B$44)-IF(AND(Assumptions!$B$34=1,W5>2500),AA5*0.01,0) | AC5: =T5*Assumptions!$B$35+P5*Assumptions!$B$36 | AD5: =AD4+B5 | AE5: =Z5+V5
A6: 5 | B6: =Assumptions!$B$5*(1+Assumptions!$B$6)^(A6-1)*Assumptions!$B$42 | C6: =Assumptions!$B$9*C5+B5*Assumptions!$B$8 | D6: =B6+C6 | E6: =B6*Assumptions!$B$12 | F6: =E6*Assumptions!$B$13+D6*Assumptions!$B$14 | G6: =IF(A6<=Assumptions!$B$23,F6*Assumptions!$B$22,0) | H6: =(F6-G6)*(1-Assumptions!$B$15) | I6: =(F6-G6)*Assumptions!$B$15 | J6: =IF(A6<=Assumptions!$B$25,Assumptions!$B$46,Assumptions!$B$20) | K6: =K5*(1-Assumptions!$B$28)+H6 | L6: =SUM(I2:I6) | M6: 0 | N6: =L6+M6 | O6: =O5+G6 | P6: =K6+N6+O6 | Q6: =K6*Assumptions!$B$19 | R6: =SUMPRODUCT(I2:I6,J2:J6)/12+M6*Assumptions!$B$20/12 | S6: =G6*Assumptions!$B$21 | T6: =MAX(D6-P6,0) | U6: =T6*Assumptions!$B$10 | V6: =U6*Assumptions!$B$38*Assumptions!$B$37/1000*30.4 | W6: =Q6+R6+S6 | X6: =Assumptions!$B$43*(F6+K6)*0.3 | Y6: =IF(AND(Assumptions!$B$34=1,W6>2500),W6*0.01,0) | Z6: =W6*(1-Assumptions!$B$44)-X6-Y6 | AA6: =Q6+R6 | AB6: =AA6*(1-Assumptions!$B$44)-IF(AND(Assumptions!$B$34=1,W6>2500),AA6*0.01,0) | AC6: =T6*Assumptions!$B$35+P6*Assumptions!$B$36 | AD6: =AD5+B6 | AE6: =Z6+V6
A7: 6 | B7: =Assumptions!$B$5*(1+Assumptions!$B$6)^(A7-1)*Assumptions!$B$42 | C7: =Assumptions!$B$9*C6+B6*Assumptions!$B$8 | D7: =B7+C7 | E7: =B7*Assumptions!$B$12 | F7: =E7*Assumptions!$B$13+D7*Assumptions!$B$14 | G7: =IF(A7<=Assumptions!$B$23,F7*Assumptions!$B$22,0) | H7: =(F7-G7)*(1-Assumptions!$B$15) | I7: =(F7-G7)*Assumptions!$B$15 | J7: =IF(A7<=Assumptions!$B$25,Assumptions!$B$46,Assumptions!$B$20) | K7: =K6*(1-Assumptions!$B$28)+H7 | L7: =SUM(I2:I7) | M7: 0 | N7: =L7+M7 | O7: =O6+G7 | P7: =K7+N7+O7 | Q7: =K7*Assumptions!$B$19 | R7: =SUMPRODUCT(I2:I7,J2:J7)/12+M7*Assumptions!$B$20/12 | S7: =G7*Assumptions!$B$21 | T7: =MAX(D7-P7,0) | U7: =T7*Assumptions!$B$10 | V7: =U7*Assumptions!$B$38*Assumptions!$B$37/1000*30.4 | W7: =Q7+R7+S7 | X7: =Assumptions!$B$43*(F7+K7)*0.3 | Y7: =IF(AND(Assumptions!$B$34=1,W7>2500),W7*0.01,0) | Z7: =W7*(1-Assumptions!$B$44)-X7-Y7 | AA7: =Q7+R7 | AB7: =AA7*(1-Assumptions!$B$44)-IF(AND(Assumptions!$B$34=1,W7>2500),AA7*0.01,0) | AC7: =T7*Assumptions!$B$35+P7*Assumptions!$B$36 | AD7: =AD6+B7 | AE7: =Z7+V7
A8: 7 | B8: =Assumptions!$B$5*(1+Assumptions!$B$6)^(A8-1)*Assumptions!$B$42 | C8: =Assumptions!$B$9*C7+B7*Assumptions!$B$8 | D8: =B8+C8 | E8: =B8*Assumptions!$B$12 | F8: =E8*Assumptions!$B$13+D8*Assumptions!$B$14 | G8: =IF(A8<=Assumptions!$B$23,F8*Assumptions!$B$22,0) | H8: =(F8-G8)*(1-Assumptions!$B$15) | I8: =(F8-G8)*Assumptions!$B$15 | J8: =IF(A8<=Assumptions!$B$25,Assumptions!$B$46,Assumptions!$B$20) | K8: =K7*(1-Assumptions!$B$28)+H8 | L8: =SUM(I2:I8) | M8: 0 | N8: =L8+M8 | O8: =O7+G8 | P8: =K8+N8+O8 | Q8: =K8*Assumptions!$B$19 | R8: =SUMPRODUCT(I2:I8,J2:J8)/12+M8*Assumptions!$B$20/12 | S8: =G8*Assumptions!$B$21 | T8: =MAX(D8-P8,0) | U8: =T8*Assumptions!$B$10 | V8: =U8*Assumptions!$B$38*Assumptions!$B$37/1000*30.4 | W8: =Q8+R8+S8 | X8: =Assumptions!$B$43*(F8+K8)*0.3 | Y8: =IF(AND(Assumptions!$B$34=1,W8>2500),W8*0.01,0) | Z8: =W8*(1-Assumptions!$B$44)-X8-Y8 | AA8: =Q8+R8 | AB8: =AA8*(1-Assumptions!$B$44)-IF(AND(Assumptions!$B$34=1,W8>2500),AA8*0.01,0) | AC8: =T8*Assumptions!$B$35+P8*Assumptions!$B$36 | AD8: =AD7+B8 | AE8: =Z8+V8
A9: 8 | B9: =Assumptions!$B$5*(1+Assumptions!$B$6)^(A9-1)*Assumptions!$B$42 | C9: =Assumptions!$B$9*C8+B8*Assumptions!$B$8 | D9: =B9+C9 | E9: =B9*Assumptions!$B$12 | F9: =E9*Assumptions!$B$13+D9*Assumptions!$B$14 | G9: =IF(A9<=Assumptions!$B$23,F9*Assumptions!$B$22,0) | H9: =(F9-G9)*(1-Assumptions!$B$15) | I9: =(F9-G9)*Assumptions!$B$15 | J9: =IF(A9<=Assumptions!$B$25,Assumptions!$B$46,Assumptions!$B$20) | K9: =K8*(1-Assumptions!$B$28)+H9 | L9: =SUM(I2:I9) | M9: 0 | N9: =L9+M9 | O9: =O8+G9 | P9: =K9+N9+O9 | Q9: =K9*Assumptions!$B$19 | R9: =SUMPRODUCT(I2:I9,J2:J9)/12+M9*Assumptions!$B$20/12 | S9: =G9*Assumptions!$B$21 | T9: =MAX(D9-P9,0) | U9: =T9*Assumptions!$B$10 | V9: =U9*Assumptions!$B$38*Assumptions!$B$37/1000*30.4 | W9: =Q9+R9+S9 | X9: =Assumptions!$B$43*(F9+K9)*0.3 | Y9: =IF(AND(Assumptions!$B$34=1,W9>2500),W9*0.01,0) | Z9: =W9*(1-Assumptions!$B$44)-X9-Y9 | AA9: =Q9+R9 | AB9: =AA9*(1-Assumptions!$B$44)-IF(AND(Assumptions!$B$34=1,W9>2500),AA9*0.01,0) | AC9: =T9*Assumptions!$B$35+P9*Assumptions!$B$36 | AD9: =AD8+B9 | AE9: =Z9+V9
A10: 9 | B10: =Assumptions!$B$5*(1+Assumptions!$B$6)^(A10-1)*Assumptions!$B$42 | C10: =Assumptions!$B$9*C9+B9*Assumptions!$B$8 | D10: =B10+C10 | E10: =B10*Assumptions!$B$12 | F10: =E10*Assumptions!$B$13+D10*Assumptions!$B$14 | G10: =IF(A10<=Assumptions!$B$23,F10*Assumptions!$B$22,0) | H10: =(F10-G10)*(1-Assumptions!$B$15) | I10: =(F10-G10)*Assumptions!$B$15 | J10: =IF(A10<=Assumptions!$B$25,Assumptions!$B$46,Assumptions!$B$20) | K10: =K9*(1-Assumptions!$B$28)+H10 | L10: =SUM(I2:I10) | M10: 0 | N10: =L10+M10 | O10: =O9+G10 | P10: =K10+N10+O10 | Q10: =K10*Assumptions!$B$19 | R10: =SUMPRODUCT(I2:I10,J2:J10)/12+M10*Assumptions!$B$20/12 | S10: =G10*Assumptions!$B$21 | T10: =MAX(D10-P10,0) | U10: =T10*Assumptions!$B$10 | V10: =U10*Assumptions!$B$38*Assumptions!$B$37/1000*30.4 | W10: =Q10+R10+S10 | X10: =Assumptions!$B$43*(F10+K10)*0.3 | Y10: =IF(AND(Assumptions!$B$34=1,W10>2500),W10*0.01,0) | Z10: =W10*(1-Assumptions!$B$44)-X10-Y10 | AA10: =Q10+R10 | AB10: =AA10*(1-Assumptions!$B$44)-IF(AND(Assumptions!$B$34=1,W10>2500),AA10*0.01,0) | AC10: =T10*Assumptions!$B$35+P10*Assumptions!$B$36 | AD10: =AD9+B10 | AE10: =Z10+V10
A11: 10 | B11: =Assumptions!$B$5*(1+Assumptions!$B$6)^(A11-1)*Assumptions!$B$42 | C11: =Assumptions!$B$9*C10+B10*Assumptions!$B$8 | D11: =B11+C11 | E11: =B11*Assumptions!$B$12 | F11: =E11*Assumptions!$B$13+D11*Assumptions!$B$14 | G11: =IF(A11<=Assumptions!$B$23,F11*Assumptions!$B$22,0) | H11: =(F11-G11)*(1-Assumptions!$B$15) | I11: =(F11-G11)*Assumptions!$B$15 | J11: =IF(A11<=Assumptions!$B$25,Assumptions!$B$46,Assumptions!$B$20) | K11: =K10*(1-Assumptions!$B$28)+H11 | L11: =SUM(I2:I11) | M11: 0 | N11: =L11+M11 | O11: =O10+G11 | P11: =K11+N11+O11 | Q11: =K11*Assumptions!$B$19 | R11: =SUMPRODUCT(I2:I11,J2:J11)/12+M11*Assumptions!$B$20/12 | S11: =G11*Assumptions!$B$21 | T11: =MAX(D11-P11,0) | U11: =T11*Assumptions!$B$10 | V11: =U11*Assumptions!$B$38*Assumptions!$B$37/1000*30.4 | W11: =Q11+R11+S11 | X11: =Assumptions!$B$43*(F11+K11)*0.3 | Y11: =IF(AND(Assumptions!$B$34=1,W11>2500),W11*0.01,0) | Z11: =W11*(1-Assumptions!$B$44)-X11-Y11 | AA11: =Q11+R11 | AB11: =AA11*(1-Assumptions!$B$44)-IF(AND(Assumptions!$B$34=1,W11>2500),AA11*0.01,0) | AC11: =T11*Assumptions!$B$35+P11*Assumptions!$B$36 | AD11: =AD10+B11 | AE11: =Z11+V11
A12: 11 | B12: =Assumptions!$B$5*(1+Assumptions!$B$6)^(A12-1)*Assumptions!$B$42 | C12: =Assumptions!$B$9*C11+B11*Assumptions!$B$8 | D12: =B12+C12 | E12: =B12*Assumptions!$B$12 | F12: =E12*Assumptions!$B$13+D12*Assumptions!$B$14 | G12: =IF(A12<=Assumptions!$B$23,F12*Assumptions!$B$22,0) | H12: =(F12-G12)*(1-Assumptions!$B$15) | I12: =(F12-G12)*Assumptions!$B$15 | J12: =IF(A12<=Assumptions!$B$25,Assumptions!$B$46,Assumptions!$B$20) | K12: =K11*(1-Assumptions!$B$28)+H12 | L12: =SUM(I2:I12) | M12: 0 | N12: =L12+M12 | O12: =O11+G12 | P12: =K12+N12+O12 | Q12: =K12*Assumptions!$B$19 | R12: =SUMPRODUCT(I2:I12,J2:J12)/12+M12*Assumptions!$B$20/12 | S12: =G12*Assumptions!$B$21 | T12: =MAX(D12-P12,0) | U12: =T12*Assumptions!$B$10 | V12: =U12*Assumptions!$B$38*Assumptions!$B$37/1000*30.4 | W12: =Q12+R12+S12 | X12: =Assumptions!$B$43*(F12+K12)*0.3 | Y12: =IF(AND(Assumptions!$B$34=1,W12>2500),W12*0.01,0) | Z12: =W12*(1-Assumptions!$B$44)-X12-Y12 | AA12: =Q12+R12 | AB12: =AA12*(1-Assumptions!$B$44)-IF(AND(Assumptions!$B$34=1,W12>2500),AA12*0.01,0) | AC12: =T12*Assumptions!$B$35+P12*Assumptions!$B$36 | AD12: =AD11+B12 | AE12: =Z12+V12
A13: 12 | B13: =Assumptions!$B$5*(1+Assumptions!$B$6)^(A13-1)*Assumptions!$B$42 | C13: =Assumptions!$B$9*C12+B12*Assumptions!$B$8 | D13: =B13+C13 | E13: =B13*Assumptions!$B$12 | F13: =E13*Assumptions!$B$13+D13*Assumptions!$B$14 | G13: =IF(A13<=Assumptions!$B$23,F13*Assumptions!$B$22,0) | H13: =(F13-G13)*(1-Assumptions!$B$15) | I13: =(F13-G13)*Assumptions!$B$15 | J13: =IF(A13<=Assumptions!$B$25,Assumptions!$B$46,Assumptions!$B$20) | K13: =K12*(1-Assumptions!$B$28)+H13 | L13: =SUM(I2:I13) | M13: 0 | N13: =L13+M13 | O13: =O12+G13 | P13: =K13+N13+O13 | Q13: =K13*Assumptions!$B$19 | R13: =SUMPRODUCT(I2:I13,J2:J13)/12+M13*Assumptions!$B$20/12 | S13: =G13*Assumptions!$B$21 | T13: =MAX(D13-P13,0) | U13: =T13*Assumptions!$B$10 | V13: =U13*Assumptions!$B$38*Assumptions!$B$37/1000*30.4 | W13: =Q13+R13+S13 | X13: =Assumptions!$B$43*(F13+K13)*0.3 | Y13: =IF(AND(Assumptions!$B$34=1,W13>2500),W13*0.01,0) | Z13: =W13*(1-Assumptions!$B$44)-X13-Y13 | AA13: =Q13+R13 | AB13: =AA13*(1-Assumptions!$B$44)-IF(AND(Assumptions!$B$34=1,W13>2500),AA13*0.01,0) | AC13: =T13*Assumptions!$B$35+P13*Assumptions!$B$36 | AD13: =AD12+B13 | AE13: =Z13+V13
A14: 13 | B14: =Assumptions!$B$5*(1+Assumptions!$B$6)^(A14-1)*Assumptions!$B$42 | C14: =Assumptions!$B$9*C13+B13*Assumptions!$B$8 | D14: =B14+C14 | E14: =B14*Assumptions!$B$12 | F14: =E14*Assumptions!$B$13+D14*Assumptions!$B$14 | G14: =IF(A14<=Assumptions!$B$23,F14*Assumptions!$B$22,0) | H14: =(F14-G14)*(1-Assumptions!$B$15) | I14: =(F14-G14)*Assumptions!$B$15 | J14: =IF(A14<=Assumptions!$B$25,Assumptions!$B$46,Assumptions!$B$20) | K14: =K13*(1-Assumptions!$B$28)+H14 | L14: =SUM(I3:I14) | M14: =Assumptions!$B$29*SUM(I2:I2) | N14: =L14+M14 | O14: =O13+G14 | P14: =K14+N14+O14 | Q14: =K14*Assumptions!$B$19 | R14: =SUMPRODUCT(I3:I14,J3:J14)/12+M14*Assumptions!$B$20/12 | S14: =G14*Assumptions!$B$21 | T14: =MAX(D14-P14,0) | U14: =T14*Assumptions!$B$10 | V14: =U14*Assumptions!$B$38*Assumptions!$B$37/1000*30.4 | W14: =Q14+R14+S14 | X14: =Assumptions!$B$43*(F14+K14)*0.3 | Y14: =IF(AND(Assumptions!$B$34=1,W14>2500),W14*0.01,0) | Z14: =W14*(1-Assumptions!$B$44)-X14-Y14 | AA14: =Q14+R14 | AB14: =AA14*(1-Assumptions!$B$44)-IF(AND(Assumptions!$B$34=1,W14>2500),AA14*0.01,0) | AC14: =T14*Assumptions!$B$35+P14*Assumptions!$B$36 | AD14: =AD13+B14 | AE14: =Z14+V14
A15: 14 | B15: =Assumptions!$B$5*(1+Assumptions!$B$6)^(A15-1)*Assumptions!$B$42 | C15: =Assumptions!$B$9*C14+B14*Assumptions!$B$8 | D15: =B15+C15 | E15: =B15*Assumptions!$B$12 | F15: =E15*Assumptions!$B$13+D15*Assumptions!$B$14 | G15: =IF(A15<=Assumptions!$B$23,F15*Assumptions!$B$22,0) | H15: =(F15-G15)*(1-Assumptions!$B$15) | I15: =(F15-G15)*Assumptions!$B$15 | J15: =IF(A15<=Assumptions!$B$25,Assumptions!$B$46,Assumptions!$B$20) | K15: =K14*(1-Assumptions!$B$28)+H15 | L15: =SUM(I4:I15) | M15: =Assumptions!$B$29*SUM(I2:I3) | N15: =L15+M15 | O15: =O14+G15 | P15: =K15+N15+O15 | Q15: =K15*Assumptions!$B$19 | R15: =SUMPRODUCT(I4:I15,J4:J15)/12+M15*Assumptions!$B$20/12 | S15: =G15*Assumptions!$B$21 | T15: =MAX(D15-P15,0) | U15: =T15*Assumptions!$B$10 | V15: =U15*Assumptions!$B$38*Assumptions!$B$37/1000*30.4 | W15: =Q15+R15+S15 | X15: =Assumptions!$B$43*(F15+K15)*0.3 | Y15: =IF(AND(Assumptions!$B$34=1,W15>2500),W15*0.01,0) | Z15: =W15*(1-Assumptions!$B$44)-X15-Y15 | AA15: =Q15+R15 | AB15: =AA15*(1-Assumptions!$B$44)-IF(AND(Assumptions!$B$34=1,W15>2500),AA15*0.01,0) | AC15: =T15*Assumptions!$B$35+P15*Assumptions!$B$36 | AD15: =AD14+B15 | AE15: =Z15+V15
A16: 15 | B16: =Assumptions!$B$5*(1+Assumptions!$B$6)^(A16-1)*Assumptions!$B$42 | C16: =Assumptions!$B$9*C15+B15*Assumptions!$B$8 | D16: =B16+C16 | E16: =B16*Assumptions!$B$12 | F16: =E16*Assumptions!$B$13+D16*Assumptions!$B$14 | G16: =IF(A16<=Assumptions!$B$23,F16*Assumptions!$B$22,0) | H16: =(F16-G16)*(1-Assumptions!$B$15) | I16: =(F16-G16)*Assumptions!$B$15 | J16: =IF(A16<=Assumptions!$B$25,Assumptions!$B$46,Assumptions!$B$20) | K16: =K15*(1-Assumptions!$B$28)+H16 | L16: =SUM(I5:I16) | M16: =Assumptions!$B$29*SUM(I2:I4) | N16: =L16+M16 | O16: =O15+G16 | P16: =K16+N16+O16 | Q16: =K16*Assumptions!$B$19 | R16: =SUMPRODUCT(I5:I16,J5:J16)/12+M16*Assumptions!$B$20/12 | S16: =G16*Assumptions!$B$21 | T16: =MAX(D16-P16,0) | U16: =T16*Assumptions!$B$10 | V16: =U16*Assumptions!$B$38*Assumptions!$B$37/1000*30.4 | W16: =Q16+R16+S16 | X16: =Assumptions!$B$43*(F16+K16)*0.3 | Y16: =IF(AND(Assumptions!$B$34=1,W16>2500),W16*0.01,0) | Z16: =W16*(1-Assumptions!$B$44)-X16-Y16 | AA16: =Q16+R16 | AB16: =AA16*(1-Assumptions!$B$44)-IF(AND(Assumptions!$B$34=1,W16>2500),AA16*0.01,0) | AC16: =T16*Assumptions!$B$35+P16*Assumptions!$B$36 | AD16: =AD15+B16 | AE16: =Z16+V16
A17: 16 | B17: =Assumptions!$B$5*(1+Assumptions!$B$6)^(A17-1)*Assumptions!$B$42 | C17: =Assumptions!$B$9*C16+B16*Assumptions!$B$8 | D17: =B17+C17 | E17: =B17*Assumptions!$B$12 | F17: =E17*Assumptions!$B$13+D17*Assumptions!$B$14 | G17: =IF(A17<=Assumptions!$B$23,F17*Assumptions!$B$22,0) | H17: =(F17-G17)*(1-Assumptions!$B$15) | I17: =(F17-G17)*Assumptions!$B$15 | J17: =IF(A17<=Assumptions!$B$25,Assumptions!$B$46,Assumptions!$B$20) | K17: =K16*(1-Assumptions!$B$28)+H17 | L17: =SUM(I6:I17) | M17: =Assumptions!$B$29*SUM(I2:I5) | N17: =L17+M17 | O17: =O16+G17 | P17: =K17+N17+O17 | Q17: =K17*Assumptions!$B$19 | R17: =SUMPRODUCT(I6:I17,J6:J17)/12+M17*Assumptions!$B$20/12 | S17: =G17*Assumptions!$B$21 | T17: =MAX(D17-P17,0) | U17: =T17*Assumptions!$B$10 | V17: =U17*Assumptions!$B$38*Assumptions!$B$37/1000*30.4 | W17: =Q17+R17+S17 | X17: =Assumptions!$B$43*(F17+K17)*0.3 | Y17: =IF(AND(Assumptions!$B$34=1,W17>2500),W17*0.01,0) | Z17: =W17*(1-Assumptions!$B$44)-X17-Y17 | AA17: =Q17+R17 | AB17: =AA17*(1-Assumptions!$B$44)-IF(AND(Assumptions!$B$34=1,W17>2500),AA17*0.01,0) | AC17: =T17*Assumptions!$B$35+P17*Assumptions!$B$36 | AD17: =AD16+B17 | AE17: =Z17+V17
A18: 17 | B18: =Assumptions!$B$5*(1+Assumptions!$B$6)^(A18-1)*Assumptions!$B$42 | C18: =Assumptions!$B$9*C17+B17*Assumptions!$B$8 | D18: =B18+C18 | E18: =B18*Assumptions!$B$12 | F18: =E18*Assumptions!$B$13+D18*Assumptions!$B$14 | G18: =IF(A18<=Assumptions!$B$23,F18*Assumptions!$B$22,0) | H18: =(F18-G18)*(1-Assumptions!$B$15) | I18: =(F18-G18)*Assumptions!$B$15 | J18: =IF(A18<=Assumptions!$B$25,Assumptions!$B$46,Assumptions!$B$20) | K18: =K17*(1-Assumptions!$B$28)+H18 | L18: =SUM(I7:I18) | M18: =Assumptions!$B$29*SUM(I2:I6) | N18: =L18+M18 | O18: =O17+G18 | P18: =K18+N18+O18 | Q18: =K18*Assumptions!$B$19 | R18: =SUMPRODUCT(I7:I18,J7:J18)/12+M18*Assumptions!$B$20/12 | S18: =G18*Assumptions!$B$21 | T18: =MAX(D18-P18,0) | U18: =T18*Assumptions!$B$10 | V18: =U18*Assumptions!$B$38*Assumptions!$B$37/1000*30.4 | W18: =Q18+R18+S18 | X18: =Assumptions!$B$43*(F18+K18)*0.3 | Y18: =IF(AND(Assumptions!$B$34=1,W18>2500),W18*0.01,0) | Z18: =W18*(1-Assumptions!$B$44)-X18-Y18 | AA18: =Q18+R18 | AB18: =AA18*(1-Assumptions!$B$44)-IF(AND(Assumptions!$B$34=1,W18>2500),AA18*0.01,0) | AC18: =T18*Assumptions!$B$35+P18*Assumptions!$B$36 | AD18: =AD17+B18 | AE18: =Z18+V18
A19: 18 | B19: =Assumptions!$B$5*(1+Assumptions!$B$6)^(A19-1)*Assumptions!$B$42 | C19: =Assumptions!$B$9*C18+B18*Assumptions!$B$8 | D19: =B19+C19 | E19: =B19*Assumptions!$B$12 | F19: =E19*Assumptions!$B$13+D19*Assumptions!$B$14 | G19: =IF(A19<=Assumptions!$B$23,F19*Assumptions!$B$22,0) | H19: =(F19-G19)*(1-Assumptions!$B$15) | I19: =(F19-G19)*Assumptions!$B$15 | J19: =IF(A19<=Assumptions!$B$25,Assumptions!$B$46,Assumptions!$B$20) | K19: =K18*(1-Assumptions!$B$28)+H19 | L19: =SUM(I8:I19) | M19: =Assumptions!$B$29*SUM(I2:I7) | N19: =L19+M19 | O19: =O18+G19 | P19: =K19+N19+O19 | Q19: =K19*Assumptions!$B$19 | R19: =SUMPRODUCT(I8:I19,J8:J19)/12+M19*Assumptions!$B$20/12 | S19: =G19*Assumptions!$B$21 | T19: =MAX(D19-P19,0) | U19: =T19*Assumptions!$B$10 | V19: =U19*Assumptions!$B$38*Assumptions!$B$37/1000*30.4 | W19: =Q19+R19+S19 | X19: =Assumptions!$B$43*(F19+K19)*0.3 | Y19: =IF(AND(Assumptions!$B$34=1,W19>2500),W19*0.01,0) | Z19: =W19*(1-Assumptions!$B$44)-X19-Y19 | AA19: =Q19+R19 | AB19: =AA19*(1-Assumptions!$B$44)-IF(AND(Assumptions!$B$34=1,W19>2500),AA19*0.01,0) | AC19: =T19*Assumptions!$B$35+P19*Assumptions!$B$36 | AD19: =AD18+B19 | AE19: =Z19+V19
A20: 19 | B20: =Assumptions!$B$5*(1+Assumptions!$B$6)^(A20-1)*Assumptions!$B$42 | C20: =Assumptions!$B$9*C19+B19*Assumptions!$B$8 | D20: =B20+C20 | E20: =B20*Assumptions!$B$12 | F20: =E20*Assumptions!$B$13+D20*Assumptions!$B$14 | G20: =IF(A20<=Assumptions!$B$23,F20*Assumptions!$B$22,0) | H20: =(F20-G20)*(1-Assumptions!$B$15) | I20: =(F20-G20)*Assumptions!$B$15 | J20: =IF(A20<=Assumptions!$B$25,Assumptions!$B$46,Assumptions!$B$20) | K20: =K19*(1-Assumptions!$B$28)+H20 | L20: =SUM(I9:I20) | M20: =Assumptions!$B$29*SUM(I2:I8) | N20: =L20+M20 | O20: =O19+G20 | P20: =K20+N20+O20 | Q20: =K20*Assumptions!$B$19 | R20: =SUMPRODUCT(I9:I20,J9:J20)/12+M20*Assumptions!$B$20/12 | S20: =G20*Assumptions!$B$21 | T20: =MAX(D20-P20,0) | U20: =T20*Assumptions!$B$10 | V20: =U20*Assumptions!$B$38*Assumptions!$B$37/1000*30.4 | W20: =Q20+R20+S20 | X20: =Assumptions!$B$43*(F20+K20)*0.3 | Y20: =IF(AND(Assumptions!$B$34=1,W20>2500),W20*0.01,0) | Z20: =W20*(1-Assumptions!$B$44)-X20-Y20 | AA20: =Q20+R20 | AB20: =AA20*(1-Assumptions!$B$44)-IF(AND(Assumptions!$B$34=1,W20>2500),AA20*0.01,0) | AC20: =T20*Assumptions!$B$35+P20*Assumptions!$B$36 | AD20: =AD19+B20 | AE20: =Z20+V20
A21: 20 | B21: =Assumptions!$B$5*(1+Assumptions!$B$6)^(A21-1)*Assumptions!$B$42 | C21: =Assumptions!$B$9*C20+B20*Assumptions!$B$8 | D21: =B21+C21 | E21: =B21*Assumptions!$B$12 | F21: =E21*Assumptions!$B$13+D21*Assumptions!$B$14 | G21: =IF(A21<=Assumptions!$B$23,F21*Assumptions!$B$22,0) | H21: =(F21-G21)*(1-Assumptions!$B$15) | I21: =(F21-G21)*Assumptions!$B$15 | J21: =IF(A21<=Assumptions!$B$25,Assumptions!$B$46,Assumptions!$B$20) | K21: =K20*(1-Assumptions!$B$28)+H21 | L21: =SUM(I10:I21) | M21: =Assumptions!$B$29*SUM(I2:I9) | N21: =L21+M21 | O21: =O20+G21 | P21: =K21+N21+O21 | Q21: =K21*Assumptions!$B$19 | R21: =SUMPRODUCT(I10:I21,J10:J21)/12+M21*Assumptions!$B$20/12 | S21: =G21*Assumptions!$B$21 | T21: =MAX(D21-P21,0) | U21: =T21*Assumptions!$B$10 | V21: =U21*Assumptions!$B$38*Assumptions!$B$37/1000*30.4 | W21: =Q21+R21+S21 | X21: =Assumptions!$B$43*(F21+K21)*0.3 | Y21: =IF(AND(Assumptions!$B$34=1,W21>2500),W21*0.01,0) | Z21: =W21*(1-Assumptions!$B$44)-X21-Y21 | AA21: =Q21+R21 | AB21: =AA21*(1-Assumptions!$B$44)-IF(AND(Assumptions!$B$34=1,W21>2500),AA21*0.01,0) | AC21: =T21*Assumptions!$B$35+P21*Assumptions!$B$36 | AD21: =AD20+B21 | AE21: =Z21+V21
A22: 21 | B22: =Assumptions!$B$5*(1+Assumptions!$B$6)^(A22-1)*Assumptions!$B$42 | C22: =Assumptions!$B$9*C21+B21*Assumptions!$B$8 | D22: =B22+C22 | E22: =B22*Assumptions!$B$12 | F22: =E22*Assumptions!$B$13+D22*Assumptions!$B$14 | G22: =IF(A22<=Assumptions!$B$23,F22*Assumptions!$B$22,0) | H22: =(F22-G22)*(1-Assumptions!$B$15) | I22: =(F22-G22)*Assumptions!$B$15 | J22: =IF(A22<=Assumptions!$B$25,Assumptions!$B$46,Assumptions!$B$20) | K22: =K21*(1-Assumptions!$B$28)+H22 | L22: =SUM(I11:I22) | M22: =Assumptions!$B$29*SUM(I2:I10) | N22: =L22+M22 | O22: =O21+G22 | P22: =K22+N22+O22 | Q22: =K22*Assumptions!$B$19 | R22: =SUMPRODUCT(I11:I22,J11:J22)/12+M22*Assumptions!$B$20/12 | S22: =G22*Assumptions!$B$21 | T22: =MAX(D22-P22,0) | U22: =T22*Assumptions!$B$10 | V22: =U22*Assumptions!$B$38*Assumptions!$B$37/1000*30.4 | W22: =Q22+R22+S22 | X22: =Assumptions!$B$43*(F22+K22)*0.3 | Y22: =IF(AND(Assumptions!$B$34=1,W22>2500),W22*0.01,0) | Z22: =W22*(1-Assumptions!$B$44)-X22-Y22 | AA22: =Q22+R22 | AB22: =AA22*(1-Assumptions!$B$44)-IF(AND(Assumptions!$B$34=1,W22>2500),AA22*0.01,0) | AC22: =T22*Assumptions!$B$35+P22*Assumptions!$B$36 | AD22: =AD21+B22 | AE22: =Z22+V22
A23: 22 | B23: =Assumptions!$B$5*(1+Assumptions!$B$6)^(A23-1)*Assumptions!$B$42 | C23: =Assumptions!$B$9*C22+B22*Assumptions!$B$8 | D23: =B23+C23 | E23: =B23*Assumptions!$B$12 | F23: =E23*Assumptions!$B$13+D23*Assumptions!$B$14 | G23: =IF(A23<=Assumptions!$B$23,F23*Assumptions!$B$22,0) | H23: =(F23-G23)*(1-Assumptions!$B$15) | I23: =(F23-G23)*Assumptions!$B$15 | J23: =IF(A23<=Assumptions!$B$25,Assumptions!$B$46,Assumptions!$B$20) | K23: =K22*(1-Assumptions!$B$28)+H23 | L23: =SUM(I12:I23) | M23: =Assumptions!$B$29*SUM(I2:I11) | N23: =L23+M23 | O23: =O22+G23 | P23: =K23+N23+O23 | Q23: =K23*Assumptions!$B$19 | R23: =SUMPRODUCT(I12:I23,J12:J23)/12+M23*Assumptions!$B$20/12 | S23: =G23*Assumptions!$B$21 | T23: =MAX(D23-P23,0) | U23: =T23*Assumptions!$B$10 | V23: =U23*Assumptions!$B$38*Assumptions!$B$37/1000*30.4 | W23: =Q23+R23+S23 | X23: =Assumptions!$B$43*(F23+K23)*0.3 | Y23: =IF(AND(Assumptions!$B$34=1,W23>2500),W23*0.01,0) | Z23: =W23*(1-Assumptions!$B$44)-X23-Y23 | AA23: =Q23+R23 | AB23: =AA23*(1-Assumptions!$B$44)-IF(AND(Assumptions!$B$34=1,W23>2500),AA23*0.01,0) | AC23: =T23*Assumptions!$B$35+P23*Assumptions!$B$36 | AD23: =AD22+B23 | AE23: =Z23+V23
A24: 23 | B24: =Assumptions!$B$5*(1+Assumptions!$B$6)^(A24-1)*Assumptions!$B$42 | C24: =Assumptions!$B$9*C23+B23*Assumptions!$B$8 | D24: =B24+C24 | E24: =B24*Assumptions!$B$12 | F24: =E24*Assumptions!$B$13+D24*Assumptions!$B$14 | G24: =IF(A24<=Assumptions!$B$23,F24*Assumptions!$B$22,0) | H24: =(F24-G24)*(1-Assumptions!$B$15) | I24: =(F24-G24)*Assumptions!$B$15 | J24: =IF(A24<=Assumptions!$B$25,Assumptions!$B$46,Assumptions!$B$20) | K24: =K23*(1-Assumptions!$B$28)+H24 | L24: =SUM(I13:I24) | M24: =Assumptions!$B$29*SUM(I2:I12) | N24: =L24+M24 | O24: =O23+G24 | P24: =K24+N24+O24 | Q24: =K24*Assumptions!$B$19 | R24: =SUMPRODUCT(I13:I24,J13:J24)/12+M24*Assumptions!$B$20/12 | S24: =G24*Assumptions!$B$21 | T24: =MAX(D24-P24,0) | U24: =T24*Assumptions!$B$10 | V24: =U24*Assumptions!$B$38*Assumptions!$B$37/1000*30.4 | W24: =Q24+R24+S24 | X24: =Assumptions!$B$43*(F24+K24)*0.3 | Y24: =IF(AND(Assumptions!$B$34=1,W24>2500),W24*0.01,0) | Z24: =W24*(1-Assumptions!$B$44)-X24-Y24 | AA24: =Q24+R24 | AB24: =AA24*(1-Assumptions!$B$44)-IF(AND(Assumptions!$B$34=1,W24>2500),AA24*0.01,0) | AC24: =T24*Assumptions!$B$35+P24*Assumptions!$B$36 | AD24: =AD23+B24 | AE24: =Z24+V24
A25: 24 | B25: =Assumptions!$B$5*(1+Assumptions!$B$6)^(A25-1)*Assumptions!$B$42 | C25: =Assumptions!$B$9*C24+B24*Assumptions!$B$8 | D25: =B25+C25 | E25: =B25*Assumptions!$B$12 | F25: =E25*Assumptions!$B$13+D25*Assumptions!$B$14 | G25: =IF(A25<=Assumptions!$B$23,F25*Assumptions!$B$22,0) | H25: =(F25-G25)*(1-Assumptions!$B$15) | I25: =(F25-G25)*Assumptions!$B$15 | J25: =IF(A25<=Assumptions!$B$25,Assumptions!$B$46,Assumptions!$B$20) | K25: =K24*(1-Assumptions!$B$28)+H25 | L25: =SUM(I14:I25) | M25: =Assumptions!$B$29*SUM(I2:I13) | N25: =L25+M25 | O25: =O24+G25 | P25: =K25+N25+O25 | Q25: =K25*Assumptions!$B$19 | R25: =SUMPRODUCT(I14:I25,J14:J25)/12+M25*Assumptions!$B$20/12 | S25: =G25*Assumptions!$B$21 | T25: =MAX(D25-P25,0) | U25: =T25*Assumptions!$B$10 | V25: =U25*Assumptions!$B$38*Assumptions!$B$37/1000*30.4 | W25: =Q25+R25+S25 | X25: =Assumptions!$B$43*(F25+K25)*0.3 | Y25: =IF(AND(Assumptions!$B$34=1,W25>2500),W25*0.01,0) | Z25: =W25*(1-Assumptions!$B$44)-X25-Y25 | AA25: =Q25+R25 | AB25: =AA25*(1-Assumptions!$B$44)-IF(AND(Assumptions!$B$34=1,W25>2500),AA25*0.01,0) | AC25: =T25*Assumptions!$B$35+P25*Assumptions!$B$36 | AD25: =AD24+B25 | AE25: =Z25+V25

Sheet Unit Economics
A1: Unit economics (closed-form, net of fees)
A4: Net monthly price | B4: =Assumptions!$B$19*Assumptions!$B$45 | C4: price × net factor
A5: Net annual price (list) | B5: =Assumptions!$B$20*Assumptions!$B$45
A6: Net annual price (promo yr 1 blend) | B6: =Assumptions!$B$46*Assumptions!$B$45
A7: LTV — monthly plan | B7: =B4/Assumptions!$B$28 | C7: net price ÷ monthly churn
A8: LTV — annual (list) | B8: =B5+B5*Assumptions!$B$29/(1-Assumptions!$B$29) | C8: first year + renewals geometric
A9: LTV — annual (promo yr 1) | B9: =B6+B5*Assumptions!$B$29/(1-Assumptions!$B$29) | C9: discounted first year, renews at list
A10: LTV — lifetime | B10: =Assumptions!$B$21*Assumptions!$B$45 | C10: one-time net
A11: Blended LTV (new-sub mix) | B11: =(1-Assumptions!$B$15)*B7+Assumptions!$B$15*IF(Assumptions!$B$25>0,B9,B8) | C11: vs GTM assumption $60–80
A12: Install → paid rate | B12: =Assumptions!$B$12*Assumptions!$B$13
A13: CAC per paying user | B13: =Assumptions!$B$39/B12 | C13: blended CPI ÷ install→paid
A14: LTV : CAC | B14: =B11/B13 | C14: target ≥ 3×
A15: Net MRR per payer (steady state approx) | B15: =(1-Assumptions!$B$15)*B4+Assumptions!$B$15*B5/12
A16: Payback (months) | B16: =B13/B15 | C16: GTM gate ≤ 6 months
A18: What $59.99 nets, per platform
A19: iOS — Apple 15% (Small Business) | B19: =Assumptions!$B$20*(1-Assumptions!$B$31)
A20: Android — Play ≈15% effective | B20: =Assumptions!$B$20*(1-Assumptions!$B$32)
A21: Web — Stripe 3.4% + 30¢ | B21: =Assumptions!$B$20*(1-Assumptions!$B$33)-0.3
A23: GTM feasibility — LAUNCH-PLAN target: 10K users & $50K MRR by day 90
A24: Cumulative installs @ month 3 | B24: =Model!AD4 | C24: target 10,000
A25: Net MRR @ month 3 | B25: =Model!AB4 | C25: target $50,000
A26: Paying subs needed for $50K net MRR | B26: =50000/B15 | C26: =50,000 ÷ net MRR per payer

Sheet Scenarios
A1: Scenario presets — paste a column into Assumptions!B
A3: Parameter | B3: Conservative | C3: Base | D3: GTM target
A4: installs0 | B4: 4000 | C4: 12000 | D4: 30000
A5: growth | B5: 0.06 | C5: 0.1 | D5: 0.08
A6: kfactor | B6: 0.2 | C6: 0.4 | D6: 0.7
A7: d30 | B7: 0.08 | C7: 0.1 | D7: 0.12
A8: decay | B8: 0.82 | C8: 0.85 | D8: 0.88
A9: dauMau | B9: 0.2 | C9: 0.25 | D9: 0.3
A10: installTrial | B10: 0.02 | C10: 0.04 | D10: 0.069
A11: trialPaid | B11: 0.3 | C11: 0.38 | D11: 0.42
A12: drip | B12: 0.001 | C12: 0.002 | D12: 0.003
A13: annualShare | B13: 0.55 | C13: 0.65 | D13: 0.68
A14: mixIos | B14: 0.55 | C14: 0.6 | D14: 0.65
A15: mixAndroid | B15: 0.3 | C15: 0.25 | D15: 0.2
... A34: cpi | B34: 3.5 | C34: 3 | D34: 2.5
